Workbook

Sheet Summary
A1: Burnout and productivity: what problems do 5 million employees report?
A2: Companion to the analysis notebook · synthetic data from Kaggle · key figures link to the 'Groups' sheet
A4: Key figure | B4: Value
A5: Employees | B5: =Groups!D13
A6: Average burnout risk (0-100) | B6: =Groups!F13
A7: Average productivity score (0-100) | B7: =Groups!H13
A8: Share with burnout risk 70+ | B8: =Groups!J13
A9: Share in the low productivity category | B9: =Groups!K13
A10: Warning signs per person (out of 11) | B10: =Groups!L13
A11: Productivity gap, highest vs lowest group | B11: =MAX(Groups!H7:H12)-MIN(Groups!H7:H12)
A12: Burnout gap, highest vs lowest group | B12: =MAX(Groups!F7:F12)-MIN(Groups!F7:F12)
A15: Main findings
A16: 1. Burnout and productivity are linked to different factors. Burnout goes with emotional exhaustion (r 0.51) and stress (0.38); productivity goes with deep work (0.55) and task completion rate (0.36).
A17: 2. Common problems: 65% use devices late at night, 35% sleep under 6 hours, and about 30% report high stress or high emotional exhaustion.
A18: 3. The outcomes barely differ by job title or work mode (less than 0.1 points between occupations); the differences are in individual behaviour.
A19: 4. N1 (low focus + mental strain) has the highest risk: burnout 58.9, productivity 49.5.
A20: 5. The 'High' level (N2, N3, N4) contains three different main problems; N4 combines high productivity (80.4) with high burnout (55.8).
A21: 6. Short sleep and high stress are at the same level in every group, so they need company-wide measures.
A23: Sheets in this file
A24: Workplace problems | B24: Which factors go with burnout and productivity; common warning signs
A25: Groups | B25: The six employee groups: size, outcomes, problem profile
A26: Warning signs by group | B26: Which signs are concentrated in some groups and which are shared by all
A27: Groups within a risk level | B27: How groups at the same risk level differ; correlations inside each group
A28: Actions | B28: Suggested actions and KPIs for each group and for the whole company
A29: Method | B29: How the groups were built, validation figures and limitations

Sheet Workplace problems
A1: Workplace problems: what goes with burnout and low productivity
A2: Pearson correlations on 5 million employees · common warning signs
B4: Minimum |r| to count as a link | C4: 0.05
A6: Correlation of each factor with the two outcomes
A7: Source: reports/02_driver_correlation.csv. The 'direction' columns are formulas using the threshold in C4.
A8: Factor | B8: Factor group | C8: r with burnout | D8: Direction (burnout) | E8: r with productivity | F8: Direction (productivity)
A9: Emotional exhaustion | B9: Mental state | C9: 0.512 | D9: =IF(ABS(C9)<$C$4,"–",IF(C9>0,"Higher burnout","Lower burnout")) | E9: -0.1819 | F9: =IF(ABS(E9)<$C$4,"–",IF(E9>0,"Higher productivity","Lower productivity"))
A10: Stress | B10: Sleep & recovery | C10: 0.3828 | D10: =IF(ABS(C10)<$C$4,"–",IF(C10>0,"Higher burnout","Lower burnout")) | E10: -0.135 | F10: =IF(ABS(E10)<$C$4,"–",IF(E10>0,"Higher productivity","Lower productivity"))
A11: Screen time | B11: Digital load | C11: 0.2208 | D11: =IF(ABS(C11)<$C$4,"–",IF(C11>0,"Higher burnout","Lower burnout")) | E11: -0.0778 | F11: =IF(ABS(E11)<$C$4,"–",IF(E11>0,"Higher productivity","Lower productivity"))
A12: Doomscrolling | B12: Digital load | C12: 0.2003 | D12: =IF(ABS(C12)<$C$4,"–",IF(C12>0,"Higher burnout","Lower burnout")) | E12: -0.0715 | F12: =IF(ABS(E12)<$C$4,"–",IF(E12>0,"Higher productivity","Lower productivity"))
A13: Late-night device use | B13: Digital load | C13: 0.158 | D13: =IF(ABS(C13)<$C$4,"–",IF(C13>0,"Higher burnout","Lower burnout")) | E13: -0.0558 | F13: =IF(ABS(E13)<$C$4,"–",IF(E13>0,"Higher productivity","Lower productivity"))
A14: Distractions per day | B14: Focus & output | C14: 0.1522 | D14: =IF(ABS(C14)<$C$4,"–",IF(C14>0,"Higher burnout","Lower burnout")) | E14: -0.0541 | F14: =IF(ABS(E14)<$C$4,"–",IF(E14>0,"Higher productivity","Lower productivity"))
A15: Notifications per day | B15: Digital load | C15: 0.0967 | D15: =IF(ABS(C15)<$C$4,"–",IF(C15>0,"Higher burnout","Lower burnout")) | E15: -0.0339 | F15: =IF(ABS(E15)<$C$4,"–",IF(E15>0,"Higher productivity","Lower productivity"))
A16: Focus sessions per day | B16: Focus & output | C16: 0.0011 | D16: =IF(ABS(C16)<$C$4,"–",IF(C16>0,"Higher burnout","Lower burnout")) | E16: 0.2301 | F16: =IF(ABS(E16)<$C$4,"–",IF(E16>0,"Higher productivity","Lower productivity"))
A17: Motivation | B17: Mental state | C17: 0.0003 | D17: =IF(ABS(C17)<$C$4,"–",IF(C17>0,"Higher burnout","Lower burnout")) | E17: 0.229 | F17: =IF(ABS(E17)<$C$4,"–",IF(E17>0,"Higher productivity","Lower productivity"))
A18: Workspace quality | B18: Work environment | C18: 0.0001 | D18: =IF(ABS(C18)<$C$4,"–",IF(C18>0,"Higher burnout","Lower burnout")) | E18: 0.1723 | F18: =IF(ABS(E18)<$C$4,"–",IF(E18>0,"Higher productivity","Lower productivity"))
A19: Task completion rate | B19: Focus & output | C19: 0.0001 | D19: =IF(ABS(C19)<$C$4,"–",IF(C19>0,"Higher burnout","Lower burnout")) | E19: 0.3558 | F19: =IF(ABS(E19)<$C$4,"–",IF(E19>0,"Higher productivity","Lower productivity"))
A20: Concentration | B20: Focus & output | C20: 0 | D20: =IF(ABS(C20)<$C$4,"–",IF(C20>0,"Higher burnout","Lower burnout")) | E20: 0.3473 | F20: =IF(ABS(E20)<$C$4,"–",IF(E20>0,"Higher productivity","Lower productivity"))
... A33: Job satisfaction | B33: Mental state | C33: -0.2544 | D33: =IF(ABS(C33)<$C$4,"–",IF(C33>0,"Higher burnout","Lower burnout")) | E33: 0.0905 | F33: =IF(ABS(E33)<$C$4,"–",IF(E33>0,"Higher productivity","Lower productivity"))
A36: Common warning signs
A37: Source: reports/02_red_flags.csv. Share = employees / total on the 'Groups' sheet.
A38: Warning sign | B38: Employees | C38: Share
A39: Late-night device use | B39: 3249966 | C39: =B39/Groups!$D$13
A40: Sleep under 6 h | B40: 1747338 | C40: =B40/Groups!$D$13
A41: High emotional exhaustion (8+) | B41: 1500117 | C41: =B41/Groups!$D$13
A42: High mental fatigue (8+) | B42: 1499460 | C42: =B42/Groups!$D$13
A43: High stress (8+) | B43: 1499416 | C43: =B43/Groups!$D$13
A44: Low job satisfaction (3 or less) | B44: 1498398 | C44: =B44/Groups!$D$13
A45: Low motivation (3 or less) | B45: 1470561 | C45: =B45/Groups!$D$13
A46: Deep work under 2 h | B46: 1370849 | C46: =B46/Groups!$D$13
A47: Screen time over 10 h | B47: 1030392 | C47: =B47/Groups!$D$13
A48: Burnout risk 70+ | B48: 894559 | C48: =B48/Groups!$D$13
A49: Low productivity category | B49: 841484 | C49: =B49/Groups!$D$13
A50: Thresholds (for example sleep under 6 hours, stress of 8+) are analysis choices, defined in src/config.py.

Sheet Groups
A1: Six employee groups
A2: K-Means on 5 million employees · ordered by priority for support · gaps from the average are formulas
A4: Overview
A5: Source: reports/03_segment_summary.csv (exported by the notebook). The 'All' row is weighted by group size.
A6: Code | B6: Group | C6: Risk level | D6: Employees | E6: Share | F6: Burnout avg | G6: Burnout gap | H6: Productivity avg | I6: Productivity gap | J6: % burnout 70+ | K6: % low productivity | L6: Warning signs / person | M6: Risk score
A7: N1 | B7: Low focus + mental strain | C7: Very high | D7: 835607 | E7: =D7/$D$13 | F7: 58.8874 | G7: =F7-$F$13 | H7: 49.5116 | I7: =H7-$H$13 | J7: 0.310119 | K7: 0.49591 | L7: 4.6896 | M7: 1.487
A8: N2 | B8: Heavy device use | C8: High | D8: 829775 | E8: =D8/$D$13 | F8: 54.5617 | G8: =F8-$F$13 | H8: 67.8528 | I8: =H8-$H$13 | J8: 0.241179 | K8: 0.161102 | L8: 3.5881 | M8: 0.4379
A9: N3 | B9: Low focus + low mental strain | C9: High | D9: 836373 | E9: =D9/$D$13 | F9: 41.1937 | G9: =F9-$F$13 | H9: 63.8357 | I9: =H9-$H$13 | J9: 0.089953 | K9: 0.232737 | L9: 2.6939 | M9: 0.3539
A10: N4 | B10: Mental strain + strong focus | C10: High | D10: 839807 | E10: =D10/$D$13 | F10: 55.7589 | G10: =F10-$F$13 | H10: 80.429 | I10: =H10-$H$13 | J10: 0.260729 | K10: 0.047437 | L10: 3.9673 | M10: 0.3251
A11: N5 | B11: Light device use | C11: Low | D11: 824113 | E11: =D11/$D$13 | F11: 42.6029 | G11: =F11-$F$13 | H11: 76.1901 | I11: =H11-$H$13 | J11: 0.100364 | K11: 0.067554 | L11: 2.7466 | M11: 0
A12: N6 | B12: Strong focus + low mental strain | C12: Low | D12: 834325 | E12: =D12/$D$13 | F12: 38.4124 | G12: =F12-$F$13 | H12: 90.8764 | I12: =H12-$H$13 | J12: 0.069985 | K12: 0.003901 | L12: 2.2272 | M12: 0
A13: All | B13: All employees | D13: =SUM(D7:D12) | E13: =SUM(E7:E12) | F13: =SUMPRODUCT($D$7:$D$12,F7:F12)/$D$13 | H13: =SUMPRODUCT($D$7:$D$12,H7:H12)/$D$13 | J13: =SUMPRODUCT($D$7:$D$12,J7:J12)/$D$13 | K13: =SUMPRODUCT($D$7:$D$12,K7:K12)/$D$13 | L13: =SUMPRODUCT($D$7:$D$12,L7:L12)/$D$13
A14: Risk score = how far burnout is above average + how far productivity is below average (in standard deviations). High productivity does not cancel out high burnout.
A34: Problem profile of each group
A35: Standard deviations from the all-employee average; positive (red) = worse than average. Source: reports/03_segment_problem_scores.csv.
A36: Code | B36: Group | C36: Digital overload | D36: Poor recovery | E36: Low focus | F36: Mental strain | G36: Poor environment
A37: N1 | B37: =B7 | C37: 0.0045 | D37: 0.0002 | E37: 1.0257 | F37: 0.982 | G37: -0.0014
A38: N2 | B38: =B8 | C38: 1.0464 | D38: 0.0012 | E38: 0.0168 | F38: -0.0025 | G38: 0.0009
A39: N3 | B39: =B9 | C39: 0.0001 | D39: -0.0007 | E39: 0.9256 | F39: -1.0838 | G39: -0.0005
A40: N4 | B40: =B10 | C40: 0.0002 | D40: 0.0017 | E40: -0.9448 | F40: 1.063 | G40: 0.0012
A41: N5 | B41: =B11 | C41: -1.061 | D41: -0.0043 | E41: 0.0232 | F41: -0.002 | G41: -0.0006
A42: N6 | B42: =B12 | C42: 0.0025 | D42: 0.0019 | E42: -1.0439 | F42: -0.9626 | G42: 0.0005

Sheet Warning signs by group
A1: Warning signs by group
A2: Which signs are concentrated in a few groups, and which are at the same level everywhere (→ company-wide measures)
B4: Max gap for 'all groups' (pp) | C4: 5
A6: Share of each group
A7: Source: reports/03_segment_red_flags.csv. The 'Gap' and 'Scope' columns are formulas.
A8: Warning sign | B8: N1 | C8: N2 | D8: N3 | E8: N4 | F8: N5 | G8: N6 | H8: All | I8: Gap (pp) | J8: Scope of action
A9: Late-night device use | B9: 0.65733 | C9: 0.82767 | D9: 0.65604 | E9: 0.65581 | F9: 0.44455 | G9: 0.65695 | H9: 0.64999 | I9: =(MAX(B9:G9)-MIN(B9:G9))*100 | J9: =IF(I9<$C$4,"Company-wide","By group")
A10: Sleep under 6 h | B10: 0.34974 | C10: 0.34981 | D10: 0.34953 | E10: 0.3496 | F10: 0.34896 | G10: 0.34917 | H10: 0.34947 | I10: =(MAX(B10:G10)-MIN(B10:G10))*100 | J10: =IF(I10<$C$4,"Company-wide","By group")
A11: High emotional exhaustion (8+) | B11: 0.48743 | C11: 0.28104 | D11: 0.11336 | E11: 0.50557 | F11: 0.28118 | G11: 0.13004 | H11: 0.30002 | I11: =(MAX(B11:G11)-MIN(B11:G11))*100 | J11: =IF(I11<$C$4,"Company-wide","By group")
A12: High mental fatigue (8+) | B12: 0.48632 | C12: 0.28185 | D12: 0.1126 | E12: 0.5054 | F12: 0.28135 | G12: 0.13034 | H12: 0.29989 | I12: =(MAX(B12:G12)-MIN(B12:G12))*100 | J12: =IF(I12<$C$4,"Company-wide","By group")
A13: High stress (8+) | B13: 0.29966 | C13: 0.30042 | D13: 0.29876 | E13: 0.30053 | F13: 0.29942 | G13: 0.3005 | H13: 0.29988 | I13: =(MAX(B13:G13)-MIN(B13:G13))*100 | J13: =IF(I13<$C$4,"Company-wide","By group")
A14: Low job satisfaction (3 or less) | B14: 0.48747 | C14: 0.28062 | D14: 0.1128 | E14: 0.5049 | F14: 0.28076 | G14: 0.13001 | H14: 0.29968 | I14: =(MAX(B14:G14)-MIN(B14:G14))*100 | J14: =IF(I14<$C$4,"Company-wide","By group")
A15: Low motivation (3 or less) | B15: 0.47938 | C15: 0.27421 | D15: 0.11074 | E15: 0.49593 | F15: 0.27566 | G15: 0.12726 | H15: 0.29411 | I15: =(MAX(B15:G15)-MIN(B15:G15))*100 | J15: =IF(I15<$C$4,"Company-wide","By group")
A16: Deep work under 2 h | B16: 0.43459 | C16: 0.26265 | D16: 0.41585 | E16: 0.13983 | F16: 0.26449 | G16: 0.12771 | H16: 0.27417 | I16: =(MAX(B16:G16)-MIN(B16:G16))*100 | J16: =IF(I16<$C$4,"Company-wide","By group")
A17: Screen time over 10 h | B17: 0.20167 | C17: 0.32756 | D17: 0.20152 | E17: 0.20151 | F17: 0.1023 | G17: 0.20135 | H17: 0.20608 | I17: =(MAX(B17:G17)-MIN(B17:G17))*100 | J17: =IF(I17<$C$4,"Company-wide","By group")
A18: Burnout risk 70+ | B18: 0.31012 | C18: 0.24118 | D18: 0.08995 | E18: 0.26073 | F18: 0.10036 | G18: 0.06998 | H18: 0.17891 | I18: =(MAX(B18:G18)-MIN(B18:G18))*100 | J18: =IF(I18<$C$4,"Company-wide","By group")
A19: Low productivity category | B19: 0.49591 | C19: 0.1611 | D19: 0.23274 | E19: 0.04744 | F19: 0.06755 | G19: 0.0039 | H19: 0.1683 | I19: =(MAX(B19:G19)-MIN(B19:G19))*100 | J19: =IF(I19<$C$4,"Company-wide","By group")
A20: Rows in bold red have almost the same rate in every group, so grouping does not help to target them; they call for company-wide measures.

Sheet Groups within a risk level
A1: Comparing groups that share a risk level
A2: Does the same risk level mean the same problem? Outcomes, problem profile, behaviour and correlations inside each group
B4: Min |r| to flag a sign change | C4: 0.05
B5: Min |r| for a reliable lever | C5: 0.1
A7: The 'Very high' level has only N1; see the 'Groups' sheet for its profile.
A9: 'High' risk level · N2, N3, N4
A10: Main issue of each group → N2: heavy device use; N3: low focus; N4: mental strain.
A12: a. Outcomes
A13: Linked to the 'Groups' sheet. The last column is the gap between the highest and lowest group.
A14: Measure | B14: N2 | C14: N3 | D14: N4 | E14: All | F14: Gap between groups
A15: Share of employees | B15: =Groups!E8 | C15: =Groups!E9 | D15: =Groups!E10 | E15: =Groups!E13 | F15: =MAX(B15:D15)-MIN(B15:D15)
A16: Burnout avg | B16: =Groups!F8 | C16: =Groups!F9 | D16: =Groups!F10 | E16: =Groups!F13 | F16: =MAX(B16:D16)-MIN(B16:D16)
A17: % burnout 70+ | B17: =Groups!J8 | C17: =Groups!J9 | D17: =Groups!J10 | E17: =Groups!J13 | F17: =MAX(B17:D17)-MIN(B17:D17)
A18: Productivity avg | B18: =Groups!H8 | C18: =Groups!H9 | D18: =Groups!H10 | E18: =Groups!H13 | F18: =MAX(B18:D18)-MIN(B18:D18)
A19: % low productivity | B19: =Groups!K8 | C19: =Groups!K9 | D19: =Groups!K10 | E19: =Groups!K13 | F19: =MAX(B19:D19)-MIN(B19:D19)
A20: Warning signs / person | B20: =Groups!L8 | C20: =Groups!L9 | D20: =Groups!L10 | E20: =Groups!L13 | F20: =MAX(B20:D20)-MIN(B20:D20)
A22: b. Problem profile (standard deviations, positive = worse)
A23: Linked to the problem-profile table on the 'Groups' sheet.
A24: Problem score | B24: N2 | C24: N3 | D24: N4
A25: Digital overload | B25: =Groups!C38 | C25: =Groups!C39 | D25: =Groups!C40
A26: Poor recovery | B26: =Groups!D38 | C26: =Groups!D39 | D26: =Groups!D40
A27: Low focus | B27: =Groups!E38 | C27: =Groups!E39 | D27: =Groups!E40
A28: Mental strain | B28: =Groups!F38 | C28: =Groups!F39 | D28: =Groups!F40
A29: Poor environment | B29: =Groups!G38 | C29: =Groups!G39 | D29: =Groups!G40
A32: c. Behaviours that differ most
A33: Source: reports/04_segment_raw_means.csv. Gap (SD) = (highest - lowest group) / all-employee standard deviation.
A34: Factor | B34: N2 | C34: N3 | D34: N4 | E34: All | F34: SD | G34: Gap (SD) | H34: Factor group
A35: Mental fatigue (1-10) | B35: 5.5034 | C35: 3.9368 | D35: 7.0293 | E35: 5.4996 | F35: 2.872 | G35: =(MAX(B35:D35)-MIN(B35:D35))/F35 | H35: Mental state
A36: Emotional exhaustion (1-10) | B36: 5.4947 | C36: 3.9461 | D36: 7.0339 | E36: 5.502 | F36: 2.8718 | G36: =(MAX(B36:D36)-MIN(B36:D36))/F36 | H36: Mental state
A37: Job satisfaction (1-10) | B37: 5.5061 | C37: 7.0551 | D37: 3.9724 | E37: 5.5009 | F37: 2.8725 | G37: =(MAX(B37:D37)-MIN(B37:D37))/F37 | H37: Mental state
A38: Motivation (1-10) | B38: 5.4949 | C38: 7.0282 | D38: 3.9869 | E38: 5.4895 | F38: 2.8439 | G38: =(MAX(B38:D38)-MIN(B38:D38))/F38 | H38: Mental state
A39: Distractions per day | B39: 60.193 | C39: 74.3791 | D39: 45.4675 | E39: 60.0335 | F39: 34.3501 | G39: =(MAX(B39:D39)-MIN(B39:D39))/F39 | H39: Focus & output
A40: Task completion rate (%) | B40: 69.9019 | C40: 62.6553 | D40: 77.4542 | E40: 69.9973 | F40: 17.6012 | G40: =(MAX(B40:D40)-MIN(B40:D40))/F40 | H40: Focus & output
A41: Focus sessions per day | B41: 4.4948 | C41: 3.301 | D41: 5.7163 | E41: 4.5005 | F41: 2.8727 | G41: =(MAX(B41:D41)-MIN(B41:D41))/F41 | H41: Focus & output
A42: Concentration (1-10) | B42: 5.4837 | C42: 4.3051 | D42: 6.7173 | E42: 5.5012 | F42: 2.8718 | G42: =(MAX(B42:D42)-MIN(B42:D42))/F42 | H42: Focus & output
A43: Deep work (h/day) | B43: 3.0013 | C43: 2.3495 | D43: 3.7491 | E43: 3.0346 | F43: 1.7077 | G43: =(MAX(B43:D43)-MIN(B43:D43))/F43 | H43: Focus & output
A44: Doomscrolling (h/day) | B44: 2.2941 | C44: 1.8278 | D44: 1.8287 | E44: 1.8346 | F44: 1.1322 | G44: =(MAX(B44:D44)-MIN(B44:D44))/F44 | H44: Digital load
A45: Social media (h/day) | B45: 4.2128 | C45: 3.5115 | D45: 3.512 | E45: 3.5173 | F45: 1.7418 | G45: =(MAX(B45:D45)-MIN(B45:D45))/F45 | H45: Digital load
A46: Notifications per day | B46: 253.2146 | C46: 209.2479 | D46: 209.4683 | E46: 209.438 | F46: 109.6646 | G46: =(MAX(B46:D46)-MIN(B46:D46))/F46 | H46: Digital load
... A59: Sleep quality (1-10) | B59: 5.5022 | C59: 5.502 | D59: 5.5014 | E59: 5.5026 | F59: 2.872 | G59: =(MAX(B59:D59)-MIN(B59:D59))/F59 | H59: Sleep & recovery
...

Sheet Actions
A1: Starting points for action
A2: The actions are hypotheses to test with a comparison group, then measure again with the listed KPIs
A4: By group (ordered by priority)
A5: Source: reports/05_playbook.csv. Share links to the 'Groups' sheet.
A6: Priority | B6: Code | C6: Group | D6: Risk level | E6: Share | F6: Main problems | G6: Strengths | H6: Suggested actions | I6: KPIs to track
A7: 1 | B7: N1 | C7: Low focus + mental strain | D7: Very high | E7: =Groups!E7 | F7: low focus (+1.03 SD) mental strain (+0.98 SD) | G7: – | H7: • Protected deep-work blocks or meeting-free days; fewer context switches • Training on prioritisation and time management; review the main sources of distraction • Regular 1:1s with managers; review workload and how clear the goals are • Recognition and development plans; access to counselling | I7: Deep-work hours, task completion rate, distractions per day; Emotional exhaustion, job satisfaction, attrition
A8: 2 | B8: N2 | C8: Heavy device use | D8: High | E8: =Groups!E8 | F8: heavy device use (+1.05 SD) | G8: – | H8: • Right-to-disconnect policy after hours; turn off non-urgent notifications • Batch notifications into set times; fewer chat channels; coaching on digital habits | I8: Screen time, % late-night device use, notifications per day
A9: 3 | B9: N3 | C9: Low focus + low mental strain | D9: High | E9: =Groups!E9 | F9: low focus (+0.93 SD) | G9: low mental strain (-1.08 SD) | H9: • Protected deep-work blocks or meeting-free days; fewer context switches • Training on prioritisation and time management; review the main sources of distraction | I9: Deep-work hours, task completion rate, distractions per day
A10: 4 | B10: N4 | C10: Mental strain + strong focus | D10: High | E10: =Groups!E10 | F10: mental strain (+1.06 SD) | G10: strong focus (-0.94 SD) | H10: • Regular 1:1s with managers; review workload and how clear the goals are • Recognition and development plans; access to counselling | I10: Emotional exhaustion, job satisfaction, attrition
A11: 5 | B11: N5 | C11: Light device use | D11: Low | E11: =Groups!E11 | F11: – | G11: light device use (-1.06 SD) | H11: • Keep current practices; use as a comparison group and as peer mentors | I11: Keep current levels; use as a comparison group
A12: 6 | B12: N6 | C12: Strong focus + low mental strain | D12: Low | E12: =Groups!E12 | F12: – | G12: strong focus (-1.04 SD) low mental strain (-0.96 SD) | H12: • Keep current practices; use as a comparison group and as peer mentors | I12: Keep current levels; use as a comparison group
A15: Company-wide
A16: Warning signs at almost the same rate in every group (see 'Warning signs by group').
A17: Warning sign | B17: Share | C17: Gap between groups (pp) | D17: Company-wide action
A18: Sleep under 6 h | B18: 0.3495 | C18: 0.09 | D18: Company-wide sleep health programme; no work messages after 9 pm
A19: High stress (8+) | B19: 0.2999 | C19: 0.18 | D19: Employee assistance programme (EAP) and stress-management training at all levels

Sheet Method
A1: Method and limitations
A2: Short summary; code and details are in the notebook
A4: Item | B4: Detail
A5: Data | B5: 5,000,000 employees × 34 columns; synthetic dataset from Kaggle
A6: Source | B6: https://www.kaggle.com/datasets/aiexplorer77/digital-burnout-and-productivity-analytics
A7: Step 1 | B7: Combine 25 measures into 5 problem scores: Digital overload, Poor recovery, Focus capacity, Mental strain, Work environment
A8: Step 2 | B8: Weight each score by |r| with burnout and with productivity (both outcomes count equally)
A9: Step 3 | B9: Choose k = 6: most stable (ARI of 0.8 or more across 5 runs) and best outcome separation among k = 3-6
A10: Step 4 | B10: K-Means on the full data; checked against Gaussian Mixture and Ward clustering
A11: Stability across 5 runs (ARI) | B11: 0.916
A12: Stability with equal weights (ARI) | B12: 0.35
A13: 300k sample vs full data (ARI) | B13: 0.986
A14: K-Means vs Gaussian Mixture (ARI) | B14: 0.815
A15: K-Means vs Ward (ARI) | B15: 0.264
A16: Silhouette | B16: 0.168
A17: eta² productivity / burnout | B17: 0.373 / 0.133
A18: Limitation 1 | B18: The data is synthetic: the input factors are almost unrelated to each other, which is rare in real data. Re-run on real HR data before making decisions.
A19: Limitation 2 | B19: Correlation is not causation.
A20: Limitation 3 | B20: The low silhouette means there are no natural clusters; the groups are a practical way to divide the risk space.
A21: Limitation 4 | B21: Correlations inside a group can change sign because of how the groups were formed (selection effect / Berkson's paradox).
A22: How to use this file | B22: The workbook uses formulas and recalculates when opened. Blue bold cells on a light-blue fill are inputs you can change.
